<?xml version="1.0"?>
<robot xmlns:xacro="http://www.ros.org/wiki/xacro" name="tita">
    <xacro:macro name="description">
        <link 
            name="base_link_dummy">
            <visual>
                <geometry>
                    <sphere 
                        radius="0.001"/>
                </geometry>
            </visual>
        </link>

        <joint 
            name="base_link_to_base_link_dummy" 
            type="fixed">
            <parent 
                link="base_link_dummy"/>
            <child 
                link="base_link"/>
            <origin 
                xyz="0 0 0" 
                rpy="0 0 0"/>
        </joint>

        <link
    name="base_link">
    <inertial>
      <origin
        xyz="0.020452 3.5457E-06 0.01871"
        rpy="0 0 0" />
      <mass
        value="13.2" />
      <inertia
        ixx="0.061855"
        ixy="-2.6029E-05"
        ixz="0.00081082"
        iyy="0.036934"
        iyz="-1.7269E-05"
        izz="0.071232" />
    </inertial>
    <visual>
      <origin
        xyz="0 0 0"
        rpy="0 0 0" />
      <geometry>
        <mesh
          filename="package://tita_description/meshes/base_link.STL" />
      </geometry>
      <material
        name="">
        <color
          rgba="0.75294 0.75294 0.75294 1" />
      </material>
    </visual>
    <collision>
      <!-- <origin
        xyz="0 0 0"
        rpy="0 0 0" />
      <geometry>
        <mesh
          filename="package://tita_description/meshes/base_link.STL" />
      </geometry> -->
      <origin 
        rpy="0 0 0" 
        xyz="0 0 0.017"/>
      <geometry>
        <box size="0.47 0.3 0.19"/>
      </geometry>
    </collision>
  </link>
  <link name="imu_link">
      <inertial>
        <mass value="0.001"/>
        <origin rpy="0 0 0" xyz="0 0 0"/>
        <inertia ixx="0.0001" ixy="0" ixz="0" iyy="0.0001" iyz="0" izz="0.0001"/>
      </inertial>
      <visual>
        <origin rpy="0 0 0" xyz="0 0 0"/>
        <geometry>
          <box size="0.001 0.001 0.001"/>
        </geometry>
        <material
          name="">
          <color
            rgba="0.75294 0.75294 0.75294 1" />
        </material>
      </visual>
      <collision>
        <origin rpy="0 0 0" xyz="0 0 0"/>
        <geometry>
          <box size=".001 .001 .001"/>
        </geometry>
      </collision>
  </link>
  <joint name="imu_joint" type="fixed">
      <parent link="base_link"/>
      <child link="imu_link"/>
      <origin rpy="0 0 0" xyz="0 0 0"/>
  </joint>
  <link
    name="left_hip">
    <inertial>
      <origin
        xyz="0.0016025 5.0253E-05 0.000638"
        rpy="0 0 0" />
      <mass
        value="2.064" />
      <inertia
        ixx="0.0043044"
        ixy="-1.3538E-07"
        ixz="8.054E-05"
        iyy="0.0029982"
        iyz="-1.5446E-06"
        izz="0.0022703" />
    </inertial>
    <visual>
      <origin
        xyz="0 0 0"
        rpy="0 0 0" />
      <geometry>
        <mesh
          filename="package://tita_description/meshes/left_hip.STL" />
      </geometry>
      <material
        name="">
        <color
          rgba="0.75294 0.75294 0.75294 1" />
      </material>
    </visual>
    <!-- <collision>
      <origin
        xyz="0 0 0"
        rpy="0 0 0" />
      <geometry>
        <mesh
          filename="package://tita_description/meshes/left_hip.STL" />
      </geometry>
    </collision> -->
  </link>
  <joint
    name="joint_left_hip"
    type="revolute">
    <origin
      xyz="0 0.0895 0"
      rpy="1.5708 0 1.5708" />
    <parent
      link="base_link" />
    <child
      link="left_hip" />
    <axis
      xyz="0 0 1" />
    <limit
      lower="-0.785398"
      upper="0.785398"
      effort="60"
      velocity="25" />
  </joint>
  <link
    name="left_thigh">
    <inertial>
      <origin
        xyz="0.021763 0.0019069 -0.027868"
        rpy="0 0 0" />
      <mass
        value="3.0984" />
      <inertia
        ixx="0.0029784"
        ixy="-9.6332E-05"
        ixz="7.878E-05"
        iyy="0.0064836"
        iyz="4.3691E-06"
        izz="0.0088353" />
    </inertial>
    <visual>
      <origin
        xyz="0 0 0"
        rpy="0 0 0" />
      <geometry>
        <mesh
          filename="package://tita_description/meshes/left_thigh.STL" />
      </geometry>
      <material
        name="">
        <color
          rgba="0.75294 0.75294 0.75294 1" />
      </material>
    </visual>
    <collision>
      <!-- <origin
        xyz="0 0 0"
        rpy="0 0 0" />
      <geometry>
        <mesh
          filename="package://tita_description/meshes/left_thigh.STL" />
      </geometry> -->
      <origin 
        rpy="0 0 -0.131" 
        xyz="0.1 0.021 -0.002"/>
      <geometry>
        <box size="0.2 0.09 0.05"/>
      </geometry>
    </collision>
  </link>
  <joint
    name="joint_left_thigh"
    type="revolute">
    <origin
      xyz="0.1426 0 0"
      rpy="-1.5708 0 -1.5708" />
    <parent
      link="left_hip" />
    <child
      link="left_thigh" />
    <axis
      xyz="0 0 1" />
    <limit
      lower="-1.919862"
      upper="3.490659"
      effort="60"
      velocity="25" />
  </joint>
  <link
    name="left_calf">
    <inertial>
      <origin
        xyz="0.095348 0.011698 0.001838"
        rpy="0 0 0" />
      <mass

        value="0.57244" />
      <inertia
        ixx="0.00030595"
        ixy="0.00035537"
        ixz="-0.00011764"
        iyy="0.0032009"
        iyz="1.129E-05"
        izz="0.0034209" />
    </inertial>
    <visual>
      <origin
        xyz="0 0 0"
        rpy="0 0 0" />
      <geometry>
        <mesh
          filename="package://tita_description/meshes/left_calf.STL" />
      </geometry>
      <material
        name="">
        <color
          rgba="0.75294 0.75294 0.75294 1" />
      </material>
    </visual>
    <collision>
      <!-- <origin
        xyz="0 0 0"
        rpy="0 0 0" />
      <geometry>
        <mesh
          filename="package://tita_description/meshes/left_calf.STL" />
      </geometry> -->
      <origin 
        rpy="0 0 -0.131" 
        xyz="0.1 0.021 -0.002"/>
      <geometry>
        <box size="0.2 0.07 0.05"/>
      </geometry>
    </collision>
  </link>
  <joint
    name="joint_left_calf"
    type="revolute">
    <origin
      xyz="0.2 0 0"
      rpy="0 0 0" />
    <parent
      link="left_thigh" />
    <child
      link="left_calf" />
    <axis
      xyz="0 0 1" />
    <limit
      lower="-2.670354"
      upper="-0.698132"
      effort="60"
      velocity="25" />
  </joint>
  <link
    name="left_wheel">
    <inertial>
      <origin
        xyz="-2.267E-06 -1.6471E-06 -0.00095616"
        rpy="0 0 0" />
      <mass
        value="1.5094" />
      <inertia
        ixx="0.0035466"
        ixy="6.9816E-06"
        ixz="-2.3224E-07"
        iyy="0.0035053"
        iyz="-1.7712E-08"
        izz="0.0069049" />
    </inertial>
    <visual>
      <origin
        xyz="0 0 0"
        rpy="0 0 0" />
      <geometry>
        <mesh
          filename="package://tita_description/meshes/left_wheel.STL" />
      </geometry>
      <material
        name="">
        <color
          rgba="0.69804 0.69804 0.69804 1" />
      </material>
    </visual>
    <collision>
      <!-- <origin
        xyz="0 0 0"
        rpy="0 0 0" />
      <geometry>
        <mesh
          filename="package://tita_description/meshes/left_wheel.STL" />
      </geometry> -->
      <origin 
        rpy="0 0 0" 
        xyz="0 0 0"/>
      <geometry>
        <cylinder length="0.034" radius="0.0925"/>
      </geometry>
    </collision>
  </link>
  <joint
    name="joint_left_wheel"
    type="revolute">
    <origin
      xyz="0.2 0 0.0514"
      rpy="0 0 0" />
    <parent
      link="left_calf" />
    <child
      link="left_wheel" />
    <axis
      xyz="0 0 1" />
    <limit
         lower=" -10000000000000.0"
      upper="10000000000000.0"
      effort="15"
      velocity="20" />
  </joint>
  <link
    name="right_hip">
    <inertial>
      <origin
        xyz="-0.0016025 5.0253E-05 0.00063801"
        rpy="0 0 0" />
      <mass
        value="2.064" />
      <inertia
        ixx="0.0043044"
        ixy="1.3538E-07"
        ixz="-8.054E-05"
        iyy="0.0029982"
        iyz="-1.5359E-06"
        izz="0.0022703" />
    </inertial>
    <visual>
      <origin
        xyz="0 0 0"
        rpy="0 0 0" />
      <geometry>
        <mesh
          filename="package://tita_description/meshes/right_hip.STL" />
      </geometry>
      <material
        name="">
        <color
          rgba="0.75294 0.75294 0.75294 1" />
      </material>
    </visual>
    <!-- <collision>
      <origin
        xyz="0 0 0"
        rpy="0 0 0" />
      <geometry>
        <mesh
          filename="package://tita_description/meshes/right_hip.STL" />
      </geometry>
    </collision> -->
  </link>
  <joint
    name="joint_right_hip"
    type="revolute">
    <origin
      xyz="0 -0.0895 0"
      rpy="1.5708 0 1.5708" />
    <parent
      link="base_link" />
    <child
      link="right_hip" />
    <axis
      xyz="0 0 1" />
    <limit
      lower="-0.785398"
      upper="0.785398"
      effort="60"
      velocity="25" />
  </joint>
  <link
    name="right_thigh">
    <inertial>
      <origin
        xyz="0.021763 0.0019065 0.027873"
        rpy="0 0 0" />
      <mass
        value="3.0987" />
      <inertia
        ixx="0.0029784"
        ixy="-9.6347E-05"
        ixz="-7.8776E-05"
        iyy="0.0064836"
        iyz="-4.3711E-06"
        izz="0.0088353" />
    </inertial>
    <visual>
      <origin
        xyz="0 0 0"
        rpy="0 0 0" />
      <geometry>
        <mesh
          filename="package://tita_description/meshes/right_thigh.STL" />
      </geometry>
      <material
        name="">
        <color
          rgba="0.75294 0.75294 0.75294 1" />
      </material>
    </visual>
    <collision>
      <!-- <origin
        xyz="0 0 0"
        rpy="0 0 0" />
      <geometry>
        <mesh
          filename="package://tita_description/meshes/right_thigh.STL" />
      </geometry> -->
      <origin 
        rpy="0 0 -0.131" 
        xyz="0.1 0.021 -0.002"/>
      <geometry>
        <box size="0.2 0.09 0.05"/>
      </geometry>
    </collision>
  </link>
  <joint
    name="joint_right_thigh"
    type="revolute">
    <origin
      xyz="-0.1426 0 0"
      rpy="-1.5708 0 -1.5708" />
    <parent
      link="right_hip" />
    <child
      link="right_thigh" />
    <axis
      xyz="0 0 1" />
    <limit
      lower="-1.919862"
      upper="3.490659"
      effort="60"
      velocity="25" />
  </joint>
  <link
    name="right_calf">
    <inertial>
      <origin
        xyz="0.095348 0.011698 -0.001838"
        rpy="0 0 0" />
      <mass
        value="0.57244" />
      <inertia
        ixx="0.00030595"
        ixy="0.00035537"
        ixz="0.00011764"
        iyy="0.0032009"
        iyz="-1.129E-05"
        izz="0.0034209" />
    </inertial>
    <visual>
      <origin
        xyz="0 0 0"
        rpy="0 0 0" />
      <geometry>
        <mesh
          filename="package://tita_description/meshes/right_calf.STL" />
      </geometry>
      <material
        name="">
        <color
          rgba="0.75294 0.75294 0.75294 1" />
      </material>
    </visual>
    <collision>
      <!-- <origin
        xyz="0 0 0"
        rpy="0 0 0" />
      <geometry>
        <mesh
          filename="package://tita_description/meshes/right_calf.STL" />
      </geometry> -->
      <origin 
        rpy="0 0 -0.131" 
        xyz="0.1 0.021 -0.002"/>
      <geometry>
        <box size="0.2 0.07 0.05"/>
      </geometry>
    </collision>
  </link>
  <joint
    name="joint_right_calf"
    type="revolute">
    <origin
      xyz="0.2 0 0"
      rpy="0 0 0" />
    <parent
      link="right_thigh" />
    <child
      link="right_calf" />
    <axis
      xyz="0 0 1" />
    <limit
      lower="-2.670354"
      upper="-0.698132"
      effort="60"
      velocity="25" />
  </joint>
  <link
    name="right_wheel">
    <inertial>
      <origin
        xyz="-2.3798E-06 -1.5854E-06 0.00095595"
        rpy="0 0 0" />
      <mass
        value="1.5094" />
      <inertia
        ixx="0.0035465"
        ixy="7.0548E-06"
        ixz="2.3146E-07"
        iyy="0.0035052"
        iyz="1.9287E-08"
        izz="0.0069047" />
    </inertial>
    <visual>
      <origin
        xyz="0 0 0"
        rpy="0 0 0" />
      <geometry>
        <mesh
          filename="package://tita_description/meshes/right_wheel.STL" />
      </geometry>
      <material
        name="">
        <color
          rgba="0.69804 0.69804 0.69804 1" />
      </material>
    </visual>
    <collision>
      <!-- <origin
        xyz="0 0 0"
        rpy="0 0 0" />
      <geometry>
        <mesh
          filename="package://tita_description/meshes/right_wheel.STL" />
      </geometry> -->
      <origin 
        rpy="0 0 0" 
        xyz="0 0 0"/>
      <geometry>
        <cylinder length="0.034" radius="0.0925"/>
      </geometry>
    </collision>
  </link>
  <joint
    name="joint_right_wheel"
    type="revolute">
    <origin
      xyz="0.2 0 -0.0514"
      rpy="0 0 0" />
    <parent
      link="right_calf" />
    <child
      link="right_wheel" />
    <axis
      xyz="0 0 1" />
    <limit
     lower=" -10000000000000.0"
      upper="10000000000000.0"
      effort="15"
      velocity="20" />
  </joint>
    </xacro:macro>
</robot>